[2024-06-19T10:30:33.463+0530] {local_task_job_runner.py:120} INFO - ::group::Pre task execution logs
[2024-06-19T10:30:33.479+0530] {taskinstance.py:2076} INFO - Dependencies all met for dep_context=non-requeueable deps ti=<TaskInstance: Backup_Database.send_mail manual__2024-06-19T05:00:30.343958+00:00 [queued]>
[2024-06-19T10:30:33.485+0530] {taskinstance.py:2076} INFO - Dependencies all met for dep_context=requeueable deps ti=<TaskInstance: Backup_Database.send_mail manual__2024-06-19T05:00:30.343958+00:00 [queued]>
[2024-06-19T10:30:33.485+0530] {taskinstance.py:2306} INFO - Starting attempt 1 of 2
[2024-06-19T10:30:33.501+0530] {taskinstance.py:2330} INFO - Executing <Task(EmailOperator): send_mail> on 2024-06-19 05:00:30.343958+00:00
[2024-06-19T10:30:33.503+0530] {standard_task_runner.py:63} INFO - Started process 4881 to run task
[2024-06-19T10:30:33.506+0530] {standard_task_runner.py:90} INFO - Running: ['airflow', 'tasks', 'run', 'Backup_Database', 'send_mail', 'manual__2024-06-19T05:00:30.343958+00:00', '--job-id', '138', '--raw', '--subdir', 'DAGS_FOLDER/basic.py', '--cfg-path', '/tmp/tmpc169kb5b']
[2024-06-19T10:30:33.509+0530] {standard_task_runner.py:91} INFO - Job 138: Subtask send_mail
[2024-06-19T10:30:33.554+0530] {task_command.py:426} INFO - Running <TaskInstance: Backup_Database.send_mail manual__2024-06-19T05:00:30.343958+00:00 [running]> on host FN-21052948.
[2024-06-19T10:30:33.635+0530] {taskinstance.py:2648} INFO - Exporting env vars: AIRFLOW_CTX_DAG_OWNER='sarika' AIRFLOW_CTX_DAG_ID='Backup_Database' AIRFLOW_CTX_TASK_ID='send_mail' AIRFLOW_CTX_EXECUTION_DATE='2024-06-19T05:00:30.343958+00:00' AIRFLOW_CTX_TRY_NUMBER='1' AIRFLOW_CTX_DAG_RUN_ID='manual__2024-06-19T05:00:30.343958+00:00'
[2024-06-19T10:30:33.636+0530] {taskinstance.py:430} INFO - ::endgroup::
[2024-06-19T10:30:33.654+0530] {base.py:84} INFO - Using connection ID 'smtp_default' for task execution.
[2024-06-19T10:30:33.654+0530] {email.py:271} INFO - Email alerting: attempt 1
[2024-06-19T10:30:36.175+0530] {taskinstance.py:441} INFO - ::group::Post task execution logs
[2024-06-19T10:30:36.177+0530] {taskinstance.py:2905} ERROR - Task failed with exception
Traceback (most recent call last):
  File "/home/kiit/airflow-env/lib/python3.8/site-packages/airflow/models/taskinstance.py", line 465, in _execute_task
    result = _execute_callable(context=context, **execute_callable_kwargs)
  File "/home/kiit/airflow-env/lib/python3.8/site-packages/airflow/models/taskinstance.py", line 432, in _execute_callable
    return execute_callable(context=context, **execute_callable_kwargs)
  File "/home/kiit/airflow-env/lib/python3.8/site-packages/airflow/models/baseoperator.py", line 401, in wrapper
    return func(self, *args, **kwargs)
  File "/home/kiit/airflow-env/lib/python3.8/site-packages/airflow/operators/email.py", line 79, in execute
    send_email(
  File "/home/kiit/airflow-env/lib/python3.8/site-packages/airflow/utils/email.py", line 80, in send_email
    return backend(
  File "/home/kiit/airflow-env/lib/python3.8/site-packages/airflow/utils/email.py", line 154, in send_email_smtp
    send_mime_email(e_from=mail_from, e_to=recipients, mime_msg=msg, conn_id=conn_id, dryrun=dryrun)
  File "/home/kiit/airflow-env/lib/python3.8/site-packages/airflow/utils/email.py", line 281, in send_mime_email
    smtp_conn.login(smtp_user, smtp_password)
  File "/usr/lib/python3.8/smtplib.py", line 743, in login
    raise last_exception
  File "/usr/lib/python3.8/smtplib.py", line 732, in login
    (code, resp) = self.auth(
  File "/usr/lib/python3.8/smtplib.py", line 655, in auth
    raise SMTPAuthenticationError(code, resp)
smtplib.SMTPAuthenticationError: (535, b'5.7.8 Username and Password not accepted. For more information, go to\n5.7.8  https://support.google.com/mail/?p=BadCredentials d9443c01a7336-1f855e56535sm106220785ad.55 - gsmtp')
[2024-06-19T10:30:36.195+0530] {taskinstance.py:1206} INFO - Marking task as UP_FOR_RETRY. dag_id=Backup_Database, task_id=send_mail, run_id=manual__2024-06-19T05:00:30.343958+00:00, execution_date=20240619T050030, start_date=20240619T050033, end_date=20240619T050036
[2024-06-19T10:30:36.212+0530] {standard_task_runner.py:110} ERROR - Failed to execute job 138 for task send_mail ((535, b'5.7.8 Username and Password not accepted. For more information, go to\n5.7.8  https://support.google.com/mail/?p=BadCredentials d9443c01a7336-1f855e56535sm106220785ad.55 - gsmtp'); 4881)
[2024-06-19T10:30:36.220+0530] {local_task_job_runner.py:240} INFO - Task exited with return code 1
[2024-06-19T10:30:36.236+0530] {taskinstance.py:3503} INFO - 0 downstream tasks scheduled from follow-on schedule check
[2024-06-19T10:30:36.237+0530] {local_task_job_runner.py:222} INFO - ::endgroup::
