[2024-06-18T15:38:36.772+0530] {local_task_job_runner.py:120} INFO - ::group::Pre task execution logs
[2024-06-18T15:38:36.791+0530] {taskinstance.py:2076} INFO - Dependencies all met for dep_context=non-requeueable deps ti=<TaskInstance: Backup_Database.backup_task scheduled__2024-06-18T09:50:00+00:00 [queued]>
[2024-06-18T15:38:36.804+0530] {taskinstance.py:2076} INFO - Dependencies all met for dep_context=requeueable deps ti=<TaskInstance: Backup_Database.backup_task scheduled__2024-06-18T09:50:00+00:00 [queued]>
[2024-06-18T15:38:36.805+0530] {taskinstance.py:2306} INFO - Starting attempt 2 of 2
[2024-06-18T15:38:36.823+0530] {taskinstance.py:2330} INFO - Executing <Task(BashOperator): backup_task> on 2024-06-18 09:50:00+00:00
[2024-06-18T15:38:36.825+0530] {standard_task_runner.py:63} INFO - Started process 35745 to run task
[2024-06-18T15:38:36.828+0530] {standard_task_runner.py:90} INFO - Running: ['airflow', 'tasks', 'run', 'Backup_Database', 'backup_task', 'scheduled__2024-06-18T09:50:00+00:00', '--job-id', '17', '--raw', '--subdir', 'DAGS_FOLDER/basic.py', '--cfg-path', '/tmp/tmp_n9dnnt0']
[2024-06-18T15:38:36.829+0530] {standard_task_runner.py:91} INFO - Job 17: Subtask backup_task
[2024-06-18T15:38:36.881+0530] {task_command.py:426} INFO - Running <TaskInstance: Backup_Database.backup_task scheduled__2024-06-18T09:50:00+00:00 [running]> on host FN-21052948.
[2024-06-18T15:38:36.942+0530] {taskinstance.py:2648} INFO - Exporting env vars: AIRFLOW_CTX_DAG_OWNER='sarika' AIRFLOW_CTX_DAG_ID='Backup_Database' AIRFLOW_CTX_TASK_ID='backup_task' AIRFLOW_CTX_EXECUTION_DATE='2024-06-18T09:50:00+00:00' AIRFLOW_CTX_TRY_NUMBER='2' AIRFLOW_CTX_DAG_RUN_ID='scheduled__2024-06-18T09:50:00+00:00'
[2024-06-18T15:38:36.943+0530] {taskinstance.py:430} INFO - ::endgroup::
[2024-06-18T15:38:36.950+0530] {subprocess.py:63} INFO - Tmp dir root location: /tmp
[2024-06-18T15:38:36.951+0530] {subprocess.py:75} INFO - Running command: ['/usr/bin/bash', '-c', '/home/kiit/airflow/bashScripts/backup.sh ']
[2024-06-18T15:38:36.956+0530] {subprocess.py:86} INFO - Output:
[2024-06-18T15:38:36.956+0530] {subprocess.py:93} INFO - /usr/bin/bash: /home/kiit/airflow/bashScripts/backup.sh: Permission denied
[2024-06-18T15:38:36.956+0530] {subprocess.py:97} INFO - Command exited with return code 126
[2024-06-18T15:38:36.957+0530] {taskinstance.py:441} INFO - ::group::Post task execution logs
[2024-06-18T15:38:36.964+0530] {taskinstance.py:2905} ERROR - Task failed with exception
Traceback (most recent call last):
  File "/home/kiit/airflow-env/lib/python3.8/site-packages/airflow/models/taskinstance.py", line 465, in _execute_task
    result = _execute_callable(context=context, **execute_callable_kwargs)
  File "/home/kiit/airflow-env/lib/python3.8/site-packages/airflow/models/taskinstance.py", line 432, in _execute_callable
    return execute_callable(context=context, **execute_callable_kwargs)
  File "/home/kiit/airflow-env/lib/python3.8/site-packages/airflow/models/baseoperator.py", line 401, in wrapper
    return func(self, *args, **kwargs)
  File "/home/kiit/airflow-env/lib/python3.8/site-packages/airflow/operators/bash.py", line 243, in execute
    raise AirflowException(
airflow.exceptions.AirflowException: Bash command failed. The command returned a non-zero exit code 126.
[2024-06-18T15:38:36.966+0530] {taskinstance.py:1206} INFO - Marking task as FAILED. dag_id=Backup_Database, task_id=backup_task, run_id=scheduled__2024-06-18T09:50:00+00:00, execution_date=20240618T095000, start_date=20240618T100836, end_date=20240618T100836
[2024-06-18T15:38:36.981+0530] {standard_task_runner.py:110} ERROR - Failed to execute job 17 for task backup_task (Bash command failed. The command returned a non-zero exit code 126.; 35745)
[2024-06-18T15:38:37.000+0530] {local_task_job_runner.py:240} INFO - Task exited with return code 1
[2024-06-18T15:38:37.020+0530] {taskinstance.py:3503} INFO - 0 downstream tasks scheduled from follow-on schedule check
[2024-06-18T15:38:37.028+0530] {local_task_job_runner.py:222} INFO - ::endgroup::
