[2024-06-18T16:44:02.280+0530] {local_task_job_runner.py:120} INFO - ::group::Pre task execution logs
[2024-06-18T16:44:02.297+0530] {taskinstance.py:2076} INFO - Dependencies all met for dep_context=non-requeueable deps ti=<TaskInstance: Backup_Database.backup_task manual__2024-06-18T11:14:01.843081+00:00 [queued]>
[2024-06-18T16:44:02.302+0530] {taskinstance.py:2076} INFO - Dependencies all met for dep_context=requeueable deps ti=<TaskInstance: Backup_Database.backup_task manual__2024-06-18T11:14:01.843081+00:00 [queued]>
[2024-06-18T16:44:02.303+0530] {taskinstance.py:2306} INFO - Starting attempt 1 of 2
[2024-06-18T16:44:02.320+0530] {taskinstance.py:2330} INFO - Executing <Task(BashOperator): backup_task> on 2024-06-18 11:14:01.843081+00:00
[2024-06-18T16:44:02.323+0530] {standard_task_runner.py:63} INFO - Started process 37115 to run task
[2024-06-18T16:44:02.327+0530] {standard_task_runner.py:90} INFO - Running: ['airflow', 'tasks', 'run', 'Backup_Database', 'backup_task', 'manual__2024-06-18T11:14:01.843081+00:00', '--job-id', '51', '--raw', '--subdir', 'DAGS_FOLDER/basic.py', '--cfg-path', '/tmp/tmpe9r7pzxd']
[2024-06-18T16:44:02.328+0530] {standard_task_runner.py:91} INFO - Job 51: Subtask backup_task
[2024-06-18T16:44:02.374+0530] {task_command.py:426} INFO - Running <TaskInstance: Backup_Database.backup_task manual__2024-06-18T11:14:01.843081+00:00 [running]> on host FN-21052948.
[2024-06-18T16:44:02.464+0530] {taskinstance.py:2648} INFO - Exporting env vars: AIRFLOW_CTX_DAG_OWNER='sarika' AIRFLOW_CTX_DAG_ID='Backup_Database' AIRFLOW_CTX_TASK_ID='backup_task' AIRFLOW_CTX_EXECUTION_DATE='2024-06-18T11:14:01.843081+00:00' AIRFLOW_CTX_TRY_NUMBER='1' AIRFLOW_CTX_DAG_RUN_ID='manual__2024-06-18T11:14:01.843081+00:00'
[2024-06-18T16:44:02.465+0530] {taskinstance.py:430} INFO - ::endgroup::
[2024-06-18T16:44:02.473+0530] {subprocess.py:63} INFO - Tmp dir root location: /tmp
[2024-06-18T16:44:02.474+0530] {subprocess.py:75} INFO - Running command: ['/usr/bin/bash', '-c', '/home/kiit/airflow/bashScripts/backup.sh ']
[2024-06-18T16:44:02.479+0530] {subprocess.py:86} INFO - Output:
[2024-06-18T16:44:02.481+0530] {subprocess.py:93} INFO - /home/kiit/airflow/bashScripts/backup.sh: line 71: /home/kiit/airflow/bashscripts/delete.sh: No such file or directory
[2024-06-18T17:32:39.477+0530] {local_task_job_runner.py:310} WARNING - State of this instance has been externally set to restarting. Terminating instance.
[2024-06-18T17:32:39.480+0530] {local_task_job_runner.py:222} INFO - ::endgroup::
[2024-06-18T17:32:39.483+0530] {process_utils.py:132} INFO - Sending 15 to group 37115. PIDs of all processes in the group: [37116, 37118, 37115]
[2024-06-18T17:32:39.484+0530] {process_utils.py:87} INFO - Sending the signal 15 to group 37115
[2024-06-18T17:32:39.487+0530] {taskinstance.py:2611} ERROR - Received SIGTERM. Terminating subprocesses.
[2024-06-18T17:32:39.495+0530] {subprocess.py:104} INFO - Sending SIGTERM signal to process group
[2024-06-18T17:32:39.497+0530] {taskinstance.py:441} INFO - ::group::Post task execution logs
[2024-06-18T17:32:39.498+0530] {process_utils.py:80} INFO - Process psutil.Process(pid=37118, status='terminated', started='16:44:02') (37118) terminated with exit code None
[2024-06-18T17:32:39.547+0530] {taskinstance.py:2905} ERROR - Task failed with exception
Traceback (most recent call last):
  File "/home/kiit/airflow-env/lib/python3.8/site-packages/airflow/models/taskinstance.py", line 465, in _execute_task
    result = _execute_callable(context=context, **execute_callable_kwargs)
  File "/home/kiit/airflow-env/lib/python3.8/site-packages/airflow/models/taskinstance.py", line 432, in _execute_callable
    return execute_callable(context=context, **execute_callable_kwargs)
  File "/home/kiit/airflow-env/lib/python3.8/site-packages/airflow/models/baseoperator.py", line 401, in wrapper
    return func(self, *args, **kwargs)
  File "/home/kiit/airflow-env/lib/python3.8/site-packages/airflow/operators/bash.py", line 234, in execute
    result = self.subprocess_hook.run_command(
  File "/home/kiit/airflow-env/lib/python3.8/site-packages/airflow/hooks/subprocess.py", line 91, in run_command
    for raw_line in iter(self.sub_process.stdout.readline, b""):
  File "/home/kiit/airflow-env/lib/python3.8/site-packages/airflow/models/taskinstance.py", line 2613, in signal_handler
    raise AirflowTaskTerminated("Task received SIGTERM signal")
airflow.exceptions.AirflowTaskTerminated: Task received SIGTERM signal
[2024-06-18T17:32:39.558+0530] {taskinstance.py:1206} INFO - Marking task as UP_FOR_RETRY. dag_id=Backup_Database, task_id=backup_task, run_id=manual__2024-06-18T11:14:01.843081+00:00, execution_date=20240618T111401, start_date=20240618T111402, end_date=20240618T120239
[2024-06-18T17:32:39.631+0530] {process_utils.py:80} INFO - Process psutil.Process(pid=37115, status='terminated', exitcode=2, started='16:44:02') (37115) terminated with exit code 2
[2024-06-18T17:32:39.632+0530] {process_utils.py:80} INFO - Process psutil.Process(pid=37116, status='terminated', started='16:44:02') (37116) terminated with exit code None
