[2024-06-18T17:41:01.623+0530] {local_task_job_runner.py:120} INFO - ::group::Pre task execution logs
[2024-06-18T17:41:01.643+0530] {taskinstance.py:2076} INFO - Dependencies all met for dep_context=non-requeueable deps ti=<TaskInstance: Backup_Database.backup_task scheduled__2024-06-18T12:00:00+00:00 [queued]>
[2024-06-18T17:41:01.650+0530] {taskinstance.py:2076} INFO - Dependencies all met for dep_context=requeueable deps ti=<TaskInstance: Backup_Database.backup_task scheduled__2024-06-18T12:00:00+00:00 [queued]>
[2024-06-18T17:41:01.650+0530] {taskinstance.py:2306} INFO - Starting attempt 2 of 2
[2024-06-18T17:41:01.667+0530] {taskinstance.py:2330} INFO - Executing <Task(BashOperator): backup_task> on 2024-06-18 12:00:00+00:00
[2024-06-18T17:41:01.670+0530] {standard_task_runner.py:63} INFO - Started process 38015 to run task
[2024-06-18T17:41:01.674+0530] {standard_task_runner.py:90} INFO - Running: ['airflow', 'tasks', 'run', 'Backup_Database', 'backup_task', 'scheduled__2024-06-18T12:00:00+00:00', '--job-id', '65', '--raw', '--subdir', 'DAGS_FOLDER/basic.py', '--cfg-path', '/tmp/tmph54ajjtf']
[2024-06-18T17:41:01.675+0530] {standard_task_runner.py:91} INFO - Job 65: Subtask backup_task
[2024-06-18T17:41:01.727+0530] {task_command.py:426} INFO - Running <TaskInstance: Backup_Database.backup_task scheduled__2024-06-18T12:00:00+00:00 [running]> on host FN-21052948.
[2024-06-18T17:41:01.793+0530] {taskinstance.py:2648} INFO - Exporting env vars: AIRFLOW_CTX_DAG_OWNER='sarika' AIRFLOW_CTX_DAG_ID='Backup_Database' AIRFLOW_CTX_TASK_ID='backup_task' AIRFLOW_CTX_EXECUTION_DATE='2024-06-18T12:00:00+00:00' AIRFLOW_CTX_TRY_NUMBER='2' AIRFLOW_CTX_DAG_RUN_ID='scheduled__2024-06-18T12:00:00+00:00'
[2024-06-18T17:41:01.793+0530] {taskinstance.py:430} INFO - ::endgroup::
[2024-06-18T17:41:01.801+0530] {subprocess.py:63} INFO - Tmp dir root location: /tmp
[2024-06-18T17:41:01.801+0530] {subprocess.py:75} INFO - Running command: ['/usr/bin/bash', '-c', '/home/kiit/airflow/bashScripts/backup.sh ']
[2024-06-18T17:41:01.807+0530] {subprocess.py:86} INFO - Output:
[2024-06-18T17:41:01.814+0530] {subprocess.py:93} INFO - mysql: [Warning] Using a password on the command line interface can be insecure.
[2024-06-18T17:41:01.815+0530] {subprocess.py:93} INFO - ERROR 2002 (HY000): Can't connect to local MySQL server through socket '/var/run/mysqld/mysqld.sock' (13)
[2024-06-18T17:41:01.816+0530] {subprocess.py:93} INFO - Error: Unable to connect to MySQL server.
[2024-06-18T17:41:01.816+0530] {subprocess.py:97} INFO - Command exited with return code 1
[2024-06-18T17:41:01.817+0530] {taskinstance.py:441} INFO - ::group::Post task execution logs
[2024-06-18T17:41:01.826+0530] {taskinstance.py:2905} ERROR - Task failed with exception
Traceback (most recent call last):
  File "/home/kiit/airflow-env/lib/python3.8/site-packages/airflow/models/taskinstance.py", line 465, in _execute_task
    result = _execute_callable(context=context, **execute_callable_kwargs)
  File "/home/kiit/airflow-env/lib/python3.8/site-packages/airflow/models/taskinstance.py", line 432, in _execute_callable
    return execute_callable(context=context, **execute_callable_kwargs)
  File "/home/kiit/airflow-env/lib/python3.8/site-packages/airflow/models/baseoperator.py", line 401, in wrapper
    return func(self, *args, **kwargs)
  File "/home/kiit/airflow-env/lib/python3.8/site-packages/airflow/operators/bash.py", line 243, in execute
    raise AirflowException(
airflow.exceptions.AirflowException: Bash command failed. The command returned a non-zero exit code 1.
[2024-06-18T17:41:01.828+0530] {taskinstance.py:1206} INFO - Marking task as FAILED. dag_id=Backup_Database, task_id=backup_task, run_id=scheduled__2024-06-18T12:00:00+00:00, execution_date=20240618T120000, start_date=20240618T121101, end_date=20240618T121101
[2024-06-18T17:41:01.843+0530] {standard_task_runner.py:110} ERROR - Failed to execute job 65 for task backup_task (Bash command failed. The command returned a non-zero exit code 1.; 38015)
[2024-06-18T17:41:01.887+0530] {local_task_job_runner.py:240} INFO - Task exited with return code 1
[2024-06-18T17:41:01.910+0530] {taskinstance.py:3503} INFO - 0 downstream tasks scheduled from follow-on schedule check
[2024-06-18T17:41:01.921+0530] {local_task_job_runner.py:222} INFO - ::endgroup::
[2024-06-18T17:45:45.632+0530] {local_task_job_runner.py:120} INFO - ::group::Pre task execution logs
[2024-06-18T17:45:45.649+0530] {taskinstance.py:2076} INFO - Dependencies all met for dep_context=non-requeueable deps ti=<TaskInstance: Backup_Database.backup_task scheduled__2024-06-18T12:00:00+00:00 [queued]>
[2024-06-18T17:45:45.655+0530] {taskinstance.py:2076} INFO - Dependencies all met for dep_context=requeueable deps ti=<TaskInstance: Backup_Database.backup_task scheduled__2024-06-18T12:00:00+00:00 [queued]>
[2024-06-18T17:45:45.655+0530] {taskinstance.py:2306} INFO - Starting attempt 2 of 2
[2024-06-18T17:45:45.672+0530] {taskinstance.py:2330} INFO - Executing <Task(BashOperator): backup_task> on 2024-06-18 12:00:00+00:00
[2024-06-18T17:45:45.677+0530] {standard_task_runner.py:63} INFO - Started process 38100 to run task
[2024-06-18T17:45:45.680+0530] {standard_task_runner.py:90} INFO - Running: ['airflow', 'tasks', 'run', 'Backup_Database', 'backup_task', 'scheduled__2024-06-18T12:00:00+00:00', '--job-id', '68', '--raw', '--subdir', 'DAGS_FOLDER/basic.py', '--cfg-path', '/tmp/tmptjlgifbb']
[2024-06-18T17:45:45.681+0530] {standard_task_runner.py:91} INFO - Job 68: Subtask backup_task
[2024-06-18T17:45:45.739+0530] {task_command.py:426} INFO - Running <TaskInstance: Backup_Database.backup_task scheduled__2024-06-18T12:00:00+00:00 [running]> on host FN-21052948.
[2024-06-18T17:45:45.813+0530] {taskinstance.py:2648} INFO - Exporting env vars: AIRFLOW_CTX_DAG_OWNER='sarika' AIRFLOW_CTX_DAG_ID='Backup_Database' AIRFLOW_CTX_TASK_ID='backup_task' AIRFLOW_CTX_EXECUTION_DATE='2024-06-18T12:00:00+00:00' AIRFLOW_CTX_TRY_NUMBER='2' AIRFLOW_CTX_DAG_RUN_ID='scheduled__2024-06-18T12:00:00+00:00'
[2024-06-18T17:45:45.814+0530] {taskinstance.py:430} INFO - ::endgroup::
[2024-06-18T17:45:45.825+0530] {subprocess.py:63} INFO - Tmp dir root location: /tmp
[2024-06-18T17:45:45.826+0530] {subprocess.py:75} INFO - Running command: ['/usr/bin/bash', '-c', '/home/kiit/airflow/bashScripts/backup.sh ']
[2024-06-18T17:45:45.832+0530] {subprocess.py:86} INFO - Output:
[2024-06-18T17:45:45.840+0530] {subprocess.py:93} INFO - mysql: [Warning] Using a password on the command line interface can be insecure.
[2024-06-18T17:45:45.842+0530] {subprocess.py:93} INFO - ERROR 2002 (HY000): Can't connect to local MySQL server through socket '/var/run/mysqld/mysqld.sock' (13)
[2024-06-18T17:45:45.843+0530] {subprocess.py:93} INFO - Error: Unable to connect to MySQL server.
[2024-06-18T17:45:45.843+0530] {subprocess.py:97} INFO - Command exited with return code 1
[2024-06-18T17:45:45.844+0530] {taskinstance.py:441} INFO - ::group::Post task execution logs
[2024-06-18T17:45:45.852+0530] {taskinstance.py:2905} ERROR - Task failed with exception
Traceback (most recent call last):
  File "/home/kiit/airflow-env/lib/python3.8/site-packages/airflow/models/taskinstance.py", line 465, in _execute_task
    result = _execute_callable(context=context, **execute_callable_kwargs)
  File "/home/kiit/airflow-env/lib/python3.8/site-packages/airflow/models/taskinstance.py", line 432, in _execute_callable
    return execute_callable(context=context, **execute_callable_kwargs)
  File "/home/kiit/airflow-env/lib/python3.8/site-packages/airflow/models/baseoperator.py", line 401, in wrapper
    return func(self, *args, **kwargs)
  File "/home/kiit/airflow-env/lib/python3.8/site-packages/airflow/operators/bash.py", line 243, in execute
    raise AirflowException(
airflow.exceptions.AirflowException: Bash command failed. The command returned a non-zero exit code 1.
[2024-06-18T17:45:45.854+0530] {taskinstance.py:1206} INFO - Marking task as FAILED. dag_id=Backup_Database, task_id=backup_task, run_id=scheduled__2024-06-18T12:00:00+00:00, execution_date=20240618T120000, start_date=20240618T121545, end_date=20240618T121545
[2024-06-18T17:45:45.871+0530] {standard_task_runner.py:110} ERROR - Failed to execute job 68 for task backup_task (Bash command failed. The command returned a non-zero exit code 1.; 38100)
[2024-06-18T17:45:45.892+0530] {local_task_job_runner.py:240} INFO - Task exited with return code 1
[2024-06-18T17:45:45.916+0530] {taskinstance.py:3503} INFO - 0 downstream tasks scheduled from follow-on schedule check
[2024-06-18T17:45:45.927+0530] {local_task_job_runner.py:222} INFO - ::endgroup::
