[2024-06-18T17:40:00.621+0530] {local_task_job_runner.py:120} INFO - ::group::Pre task execution logs
[2024-06-18T17:40:00.647+0530] {taskinstance.py:2076} INFO - Dependencies all met for dep_context=non-requeueable deps ti=<TaskInstance: Backup_Database.backup_task scheduled__2024-06-18T12:00:00+00:00 [queued]>
[2024-06-18T17:40:00.657+0530] {taskinstance.py:2076} INFO - Dependencies all met for dep_context=requeueable deps ti=<TaskInstance: Backup_Database.backup_task scheduled__2024-06-18T12:00:00+00:00 [queued]>
[2024-06-18T17:40:00.657+0530] {taskinstance.py:2306} INFO - Starting attempt 1 of 2
[2024-06-18T17:40:00.675+0530] {taskinstance.py:2330} INFO - Executing <Task(BashOperator): backup_task> on 2024-06-18 12:00:00+00:00
[2024-06-18T17:40:00.679+0530] {standard_task_runner.py:63} INFO - Started process 37997 to run task
[2024-06-18T17:40:00.682+0530] {standard_task_runner.py:90} INFO - Running: ['airflow', 'tasks', 'run', 'Backup_Database', 'backup_task', 'scheduled__2024-06-18T12:00:00+00:00', '--job-id', '64', '--raw', '--subdir', 'DAGS_FOLDER/basic.py', '--cfg-path', '/tmp/tmpe2ajuu6x']
[2024-06-18T17:40:00.683+0530] {standard_task_runner.py:91} INFO - Job 64: Subtask backup_task
[2024-06-18T17:40:00.730+0530] {task_command.py:426} INFO - Running <TaskInstance: Backup_Database.backup_task scheduled__2024-06-18T12:00:00+00:00 [running]> on host FN-21052948.
[2024-06-18T17:40:00.809+0530] {taskinstance.py:2648} INFO - Exporting env vars: AIRFLOW_CTX_DAG_OWNER='sarika' AIRFLOW_CTX_DAG_ID='Backup_Database' AIRFLOW_CTX_TASK_ID='backup_task' AIRFLOW_CTX_EXECUTION_DATE='2024-06-18T12:00:00+00:00' AIRFLOW_CTX_TRY_NUMBER='1' AIRFLOW_CTX_DAG_RUN_ID='scheduled__2024-06-18T12:00:00+00:00'
[2024-06-18T17:40:00.810+0530] {taskinstance.py:430} INFO - ::endgroup::
[2024-06-18T17:40:00.817+0530] {subprocess.py:63} INFO - Tmp dir root location: /tmp
[2024-06-18T17:40:00.818+0530] {subprocess.py:75} INFO - Running command: ['/usr/bin/bash', '-c', '/home/kiit/airflow/bashScripts/backup.sh ']
[2024-06-18T17:40:00.822+0530] {subprocess.py:86} INFO - Output:
[2024-06-18T17:40:00.828+0530] {subprocess.py:93} INFO - mysql: [Warning] Using a password on the command line interface can be insecure.
[2024-06-18T17:40:00.829+0530] {subprocess.py:93} INFO - ERROR 2002 (HY000): Can't connect to local MySQL server through socket '/var/run/mysqld/mysqld.sock' (13)
[2024-06-18T17:40:00.829+0530] {subprocess.py:93} INFO - Error: Unable to connect to MySQL server.
[2024-06-18T17:40:00.830+0530] {subprocess.py:97} INFO - Command exited with return code 1
[2024-06-18T17:40:00.830+0530] {taskinstance.py:441} INFO - ::group::Post task execution logs
[2024-06-18T17:40:00.838+0530] {taskinstance.py:2905} ERROR - Task failed with exception
Traceback (most recent call last):
  File "/home/kiit/airflow-env/lib/python3.8/site-packages/airflow/models/taskinstance.py", line 465, in _execute_task
    result = _execute_callable(context=context, **execute_callable_kwargs)
  File "/home/kiit/airflow-env/lib/python3.8/site-packages/airflow/models/taskinstance.py", line 432, in _execute_callable
    return execute_callable(context=context, **execute_callable_kwargs)
  File "/home/kiit/airflow-env/lib/python3.8/site-packages/airflow/models/baseoperator.py", line 401, in wrapper
    return func(self, *args, **kwargs)
  File "/home/kiit/airflow-env/lib/python3.8/site-packages/airflow/operators/bash.py", line 243, in execute
    raise AirflowException(
airflow.exceptions.AirflowException: Bash command failed. The command returned a non-zero exit code 1.
[2024-06-18T17:40:00.840+0530] {taskinstance.py:1206} INFO - Marking task as UP_FOR_RETRY. dag_id=Backup_Database, task_id=backup_task, run_id=scheduled__2024-06-18T12:00:00+00:00, execution_date=20240618T120000, start_date=20240618T121000, end_date=20240618T121000
[2024-06-18T17:40:00.855+0530] {standard_task_runner.py:110} ERROR - Failed to execute job 64 for task backup_task (Bash command failed. The command returned a non-zero exit code 1.; 37997)
[2024-06-18T17:40:00.895+0530] {local_task_job_runner.py:240} INFO - Task exited with return code 1
[2024-06-18T17:40:00.913+0530] {taskinstance.py:3503} INFO - 0 downstream tasks scheduled from follow-on schedule check
[2024-06-18T17:40:00.914+0530] {local_task_job_runner.py:222} INFO - ::endgroup::
[2024-06-18T17:44:45.230+0530] {local_task_job_runner.py:120} INFO - ::group::Pre task execution logs
[2024-06-18T17:44:45.248+0530] {taskinstance.py:2076} INFO - Dependencies all met for dep_context=non-requeueable deps ti=<TaskInstance: Backup_Database.backup_task scheduled__2024-06-18T12:00:00+00:00 [queued]>
[2024-06-18T17:44:45.256+0530] {taskinstance.py:2076} INFO - Dependencies all met for dep_context=requeueable deps ti=<TaskInstance: Backup_Database.backup_task scheduled__2024-06-18T12:00:00+00:00 [queued]>
[2024-06-18T17:44:45.256+0530] {taskinstance.py:2306} INFO - Starting attempt 1 of 2
[2024-06-18T17:44:45.272+0530] {taskinstance.py:2330} INFO - Executing <Task(BashOperator): backup_task> on 2024-06-18 12:00:00+00:00
[2024-06-18T17:44:45.275+0530] {standard_task_runner.py:63} INFO - Started process 38070 to run task
[2024-06-18T17:44:45.277+0530] {standard_task_runner.py:90} INFO - Running: ['airflow', 'tasks', 'run', 'Backup_Database', 'backup_task', 'scheduled__2024-06-18T12:00:00+00:00', '--job-id', '66', '--raw', '--subdir', 'DAGS_FOLDER/basic.py', '--cfg-path', '/tmp/tmp7xv166a1']
[2024-06-18T17:44:45.279+0530] {standard_task_runner.py:91} INFO - Job 66: Subtask backup_task
[2024-06-18T17:44:45.329+0530] {task_command.py:426} INFO - Running <TaskInstance: Backup_Database.backup_task scheduled__2024-06-18T12:00:00+00:00 [running]> on host FN-21052948.
[2024-06-18T17:44:45.390+0530] {taskinstance.py:2648} INFO - Exporting env vars: AIRFLOW_CTX_DAG_OWNER='sarika' AIRFLOW_CTX_DAG_ID='Backup_Database' AIRFLOW_CTX_TASK_ID='backup_task' AIRFLOW_CTX_EXECUTION_DATE='2024-06-18T12:00:00+00:00' AIRFLOW_CTX_TRY_NUMBER='1' AIRFLOW_CTX_DAG_RUN_ID='scheduled__2024-06-18T12:00:00+00:00'
[2024-06-18T17:44:45.391+0530] {taskinstance.py:430} INFO - ::endgroup::
[2024-06-18T17:44:45.400+0530] {subprocess.py:63} INFO - Tmp dir root location: /tmp
[2024-06-18T17:44:45.400+0530] {subprocess.py:75} INFO - Running command: ['/usr/bin/bash', '-c', '/home/kiit/airflow/bashScripts/backup.sh ']
[2024-06-18T17:44:45.407+0530] {subprocess.py:86} INFO - Output:
[2024-06-18T17:44:45.417+0530] {subprocess.py:93} INFO - mysql: [Warning] Using a password on the command line interface can be insecure.
[2024-06-18T17:44:45.419+0530] {subprocess.py:93} INFO - ERROR 2002 (HY000): Can't connect to local MySQL server through socket '/var/run/mysqld/mysqld.sock' (13)
[2024-06-18T17:44:45.420+0530] {subprocess.py:93} INFO - Error: Unable to connect to MySQL server.
[2024-06-18T17:44:45.420+0530] {subprocess.py:97} INFO - Command exited with return code 1
[2024-06-18T17:44:45.421+0530] {taskinstance.py:441} INFO - ::group::Post task execution logs
[2024-06-18T17:44:45.429+0530] {taskinstance.py:2905} ERROR - Task failed with exception
Traceback (most recent call last):
  File "/home/kiit/airflow-env/lib/python3.8/site-packages/airflow/models/taskinstance.py", line 465, in _execute_task
    result = _execute_callable(context=context, **execute_callable_kwargs)
  File "/home/kiit/airflow-env/lib/python3.8/site-packages/airflow/models/taskinstance.py", line 432, in _execute_callable
    return execute_callable(context=context, **execute_callable_kwargs)
  File "/home/kiit/airflow-env/lib/python3.8/site-packages/airflow/models/baseoperator.py", line 401, in wrapper
    return func(self, *args, **kwargs)
  File "/home/kiit/airflow-env/lib/python3.8/site-packages/airflow/operators/bash.py", line 243, in execute
    raise AirflowException(
airflow.exceptions.AirflowException: Bash command failed. The command returned a non-zero exit code 1.
[2024-06-18T17:44:45.432+0530] {taskinstance.py:1206} INFO - Marking task as UP_FOR_RETRY. dag_id=Backup_Database, task_id=backup_task, run_id=scheduled__2024-06-18T12:00:00+00:00, execution_date=20240618T120000, start_date=20240618T121445, end_date=20240618T121445
[2024-06-18T17:44:45.453+0530] {standard_task_runner.py:110} ERROR - Failed to execute job 66 for task backup_task (Bash command failed. The command returned a non-zero exit code 1.; 38070)
[2024-06-18T17:44:45.490+0530] {local_task_job_runner.py:240} INFO - Task exited with return code 1
[2024-06-18T17:44:45.511+0530] {taskinstance.py:3503} INFO - 0 downstream tasks scheduled from follow-on schedule check
[2024-06-18T17:44:45.512+0530] {local_task_job_runner.py:222} INFO - ::endgroup::
