[2024-06-18T17:30:01.189+0530] {local_task_job_runner.py:120} INFO - ::group::Pre task execution logs
[2024-06-18T17:30:01.206+0530] {taskinstance.py:2076} INFO - Dependencies all met for dep_context=non-requeueable deps ti=<TaskInstance: Backup_Database.backup_task scheduled__2024-06-18T11:50:00+00:00 [queued]>
[2024-06-18T17:30:01.214+0530] {taskinstance.py:2076} INFO - Dependencies all met for dep_context=requeueable deps ti=<TaskInstance: Backup_Database.backup_task scheduled__2024-06-18T11:50:00+00:00 [queued]>
[2024-06-18T17:30:01.214+0530] {taskinstance.py:2306} INFO - Starting attempt 1 of 2
[2024-06-18T17:30:01.233+0530] {taskinstance.py:2330} INFO - Executing <Task(BashOperator): backup_task> on 2024-06-18 11:50:00+00:00
[2024-06-18T17:30:01.235+0530] {standard_task_runner.py:63} INFO - Started process 37671 to run task
[2024-06-18T17:30:01.237+0530] {standard_task_runner.py:90} INFO - Running: ['airflow', 'tasks', 'run', 'Backup_Database', 'backup_task', 'scheduled__2024-06-18T11:50:00+00:00', '--job-id', '56', '--raw', '--subdir', 'DAGS_FOLDER/basic.py', '--cfg-path', '/tmp/tmpca4cyeeg']
[2024-06-18T17:30:01.238+0530] {standard_task_runner.py:91} INFO - Job 56: Subtask backup_task
[2024-06-18T17:30:01.290+0530] {task_command.py:426} INFO - Running <TaskInstance: Backup_Database.backup_task scheduled__2024-06-18T11:50:00+00:00 [running]> on host FN-21052948.
[2024-06-18T17:30:01.365+0530] {taskinstance.py:2648} INFO - Exporting env vars: AIRFLOW_CTX_DAG_OWNER='sarika' AIRFLOW_CTX_DAG_ID='Backup_Database' AIRFLOW_CTX_TASK_ID='backup_task' AIRFLOW_CTX_EXECUTION_DATE='2024-06-18T11:50:00+00:00' AIRFLOW_CTX_TRY_NUMBER='1' AIRFLOW_CTX_DAG_RUN_ID='scheduled__2024-06-18T11:50:00+00:00'
[2024-06-18T17:30:01.366+0530] {taskinstance.py:430} INFO - ::endgroup::
[2024-06-18T17:30:01.374+0530] {subprocess.py:63} INFO - Tmp dir root location: /tmp
[2024-06-18T17:30:01.374+0530] {subprocess.py:75} INFO - Running command: ['/usr/bin/bash', '-c', '/home/kiit/airflow/bashScripts/backup.sh ']
[2024-06-18T17:30:01.383+0530] {subprocess.py:86} INFO - Output:
[2024-06-18T17:33:24.928+0530] {subprocess.py:93} INFO - Enter password:
[2024-06-18T17:33:24.929+0530] {subprocess.py:93} INFO - ERROR 2002 (HY000): Can't connect to local MySQL server through socket '/var/run/mysqld/mysqld.sock' (13)
[2024-06-18T17:33:24.930+0530] {subprocess.py:93} INFO - /home/kiit/airflow/bashScripts/backup.sh: line 87: syntax error near unexpected token `)'
[2024-06-18T17:33:24.930+0530] {subprocess.py:93} INFO - /home/kiit/airflow/bashScripts/backup.sh: line 87: `port} -sse "${SQL_QUERY}")'
[2024-06-18T17:33:24.930+0530] {subprocess.py:97} INFO - Command exited with return code 2
[2024-06-18T17:33:24.931+0530] {taskinstance.py:441} INFO - ::group::Post task execution logs
[2024-06-18T17:33:24.941+0530] {taskinstance.py:2905} ERROR - Task failed with exception
Traceback (most recent call last):
  File "/home/kiit/airflow-env/lib/python3.8/site-packages/airflow/models/taskinstance.py", line 465, in _execute_task
    result = _execute_callable(context=context, **execute_callable_kwargs)
  File "/home/kiit/airflow-env/lib/python3.8/site-packages/airflow/models/taskinstance.py", line 432, in _execute_callable
    return execute_callable(context=context, **execute_callable_kwargs)
  File "/home/kiit/airflow-env/lib/python3.8/site-packages/airflow/models/baseoperator.py", line 401, in wrapper
    return func(self, *args, **kwargs)
  File "/home/kiit/airflow-env/lib/python3.8/site-packages/airflow/operators/bash.py", line 243, in execute
    raise AirflowException(
airflow.exceptions.AirflowException: Bash command failed. The command returned a non-zero exit code 2.
[2024-06-18T17:33:24.945+0530] {taskinstance.py:1206} INFO - Marking task as UP_FOR_RETRY. dag_id=Backup_Database, task_id=backup_task, run_id=scheduled__2024-06-18T11:50:00+00:00, execution_date=20240618T115000, start_date=20240618T120001, end_date=20240618T120324
[2024-06-18T17:33:24.984+0530] {standard_task_runner.py:110} ERROR - Failed to execute job 56 for task backup_task (Bash command failed. The command returned a non-zero exit code 2.; 37671)
[2024-06-18T17:33:25.025+0530] {local_task_job_runner.py:240} INFO - Task exited with return code 1
[2024-06-18T17:33:25.044+0530] {taskinstance.py:3503} INFO - 0 downstream tasks scheduled from follow-on schedule check
[2024-06-18T17:33:25.045+0530] {local_task_job_runner.py:222} INFO - ::endgroup::
[2024-06-18T17:35:20.715+0530] {local_task_job_runner.py:120} INFO - ::group::Pre task execution logs
[2024-06-18T17:35:20.735+0530] {taskinstance.py:2076} INFO - Dependencies all met for dep_context=non-requeueable deps ti=<TaskInstance: Backup_Database.backup_task scheduled__2024-06-18T11:50:00+00:00 [queued]>
[2024-06-18T17:35:20.741+0530] {taskinstance.py:2076} INFO - Dependencies all met for dep_context=requeueable deps ti=<TaskInstance: Backup_Database.backup_task scheduled__2024-06-18T11:50:00+00:00 [queued]>
[2024-06-18T17:35:20.742+0530] {taskinstance.py:2306} INFO - Starting attempt 1 of 2
[2024-06-18T17:35:20.757+0530] {taskinstance.py:2330} INFO - Executing <Task(BashOperator): backup_task> on 2024-06-18 11:50:00+00:00
[2024-06-18T17:35:20.760+0530] {standard_task_runner.py:63} INFO - Started process 37914 to run task
[2024-06-18T17:35:20.764+0530] {standard_task_runner.py:90} INFO - Running: ['airflow', 'tasks', 'run', 'Backup_Database', 'backup_task', 'scheduled__2024-06-18T11:50:00+00:00', '--job-id', '60', '--raw', '--subdir', 'DAGS_FOLDER/basic.py', '--cfg-path', '/tmp/tmp6hxy8yut']
[2024-06-18T17:35:20.766+0530] {standard_task_runner.py:91} INFO - Job 60: Subtask backup_task
[2024-06-18T17:35:20.820+0530] {task_command.py:426} INFO - Running <TaskInstance: Backup_Database.backup_task scheduled__2024-06-18T11:50:00+00:00 [running]> on host FN-21052948.
[2024-06-18T17:35:20.892+0530] {taskinstance.py:2648} INFO - Exporting env vars: AIRFLOW_CTX_DAG_OWNER='sarika' AIRFLOW_CTX_DAG_ID='Backup_Database' AIRFLOW_CTX_TASK_ID='backup_task' AIRFLOW_CTX_EXECUTION_DATE='2024-06-18T11:50:00+00:00' AIRFLOW_CTX_TRY_NUMBER='1' AIRFLOW_CTX_DAG_RUN_ID='scheduled__2024-06-18T11:50:00+00:00'
[2024-06-18T17:35:20.893+0530] {taskinstance.py:430} INFO - ::endgroup::
[2024-06-18T17:35:20.902+0530] {subprocess.py:63} INFO - Tmp dir root location: /tmp
[2024-06-18T17:35:20.902+0530] {subprocess.py:75} INFO - Running command: ['/usr/bin/bash', '-c', '/home/kiit/airflow/bashScripts/backup.sh ']
[2024-06-18T17:35:20.910+0530] {subprocess.py:86} INFO - Output:
[2024-06-18T17:35:20.918+0530] {subprocess.py:93} INFO - mysql: [Warning] Using a password on the command line interface can be insecure.
[2024-06-18T17:35:20.919+0530] {subprocess.py:93} INFO - ERROR 2002 (HY000): Can't connect to local MySQL server through socket '/var/run/mysqld/mysqld.sock' (13)
[2024-06-18T17:35:20.920+0530] {subprocess.py:93} INFO - Error: Unable to connect to MySQL server.
[2024-06-18T17:35:20.920+0530] {subprocess.py:97} INFO - Command exited with return code 1
[2024-06-18T17:35:20.920+0530] {taskinstance.py:441} INFO - ::group::Post task execution logs
[2024-06-18T17:35:20.928+0530] {taskinstance.py:2905} ERROR - Task failed with exception
Traceback (most recent call last):
  File "/home/kiit/airflow-env/lib/python3.8/site-packages/airflow/models/taskinstance.py", line 465, in _execute_task
    result = _execute_callable(context=context, **execute_callable_kwargs)
  File "/home/kiit/airflow-env/lib/python3.8/site-packages/airflow/models/taskinstance.py", line 432, in _execute_callable
    return execute_callable(context=context, **execute_callable_kwargs)
  File "/home/kiit/airflow-env/lib/python3.8/site-packages/airflow/models/baseoperator.py", line 401, in wrapper
    return func(self, *args, **kwargs)
  File "/home/kiit/airflow-env/lib/python3.8/site-packages/airflow/operators/bash.py", line 243, in execute
    raise AirflowException(
airflow.exceptions.AirflowException: Bash command failed. The command returned a non-zero exit code 1.
[2024-06-18T17:35:20.931+0530] {taskinstance.py:1206} INFO - Marking task as UP_FOR_RETRY. dag_id=Backup_Database, task_id=backup_task, run_id=scheduled__2024-06-18T11:50:00+00:00, execution_date=20240618T115000, start_date=20240618T120520, end_date=20240618T120520
[2024-06-18T17:35:20.944+0530] {standard_task_runner.py:110} ERROR - Failed to execute job 60 for task backup_task (Bash command failed. The command returned a non-zero exit code 1.; 37914)
[2024-06-18T17:35:20.975+0530] {local_task_job_runner.py:240} INFO - Task exited with return code 1
[2024-06-18T17:35:20.998+0530] {taskinstance.py:3503} INFO - 0 downstream tasks scheduled from follow-on schedule check
[2024-06-18T17:35:20.999+0530] {local_task_job_runner.py:222} INFO - ::endgroup::
